<?xml version="1.0" ?>
<sdf version="1.5">
  <model name="quadrotor">
    <plugin name="model_location" filename="libmodel_location.so"/>
    <plugin name="model_push_torque" filename="libmodel_push_torque.so"/>
    <link name="quadrotor_link">
      <pose>0 0 0.182466 0 0 0</pose>
      <inertial>
        <mass>1.316</mass>
        <inertia>
          <ixx>0.0128</ixx>
          <ixy>0</ixy>
          <ixz>0</ixz>
          <iyy>0.0128</iyy>
          <iyz>0</iyz>
          <izz>0.0218</izz>
        </inertia>
      </inertial>
      <collision name="collision">
        <geometry>
          <mesh>
            <uri>model://quadrotor/meshes/quadrotor_base.dae</uri>
          </mesh>
        </geometry>
      </collision>
      <visual name="visual">
        <geometry>
          <mesh>
            <uri>model://quadrotor/meshes/quadrotor_base.dae</uri>
          </mesh>
        </geometry>
      </visual>
      <sensor name='imu_sensor' type='imu'>
        <always_on>1</always_on>
        <update_rate>100</update_rate>
        <imu>
          <angular_velocity>
            <x>
              <noise type="gaussian">
               <mean>0</mean>
               <stddev>0.0002</stddev>
               <bias_mean>7.5e-06</bias_mean>
               <bias_stddev>8e-07</bias_stddev>
              </noise>
            </x>
            <y>
              <noise type="gaussian">
               <mean>0</mean>
               <stddev>0.0002</stddev>
               <bias_mean>7.5e-06</bias_mean>
               <bias_stddev>8e-07</bias_stddev>
              </noise>
            </y>
            <z>
              <noise type="gaussian">
               <mean>0</mean>
               <stddev>0.0002</stddev>
               <bias_mean>7.5e-06</bias_mean>
               <bias_stddev>8e-07</bias_stddev>
              </noise>
            </z>
          </angular_velocity>

          <linear_acceleration>
            <x>
              <noise type="gaussian">
                <mean>0</mean>
                <stddev>0.017</stddev>
                <bias_mean>0.1</bias_mean>
                <bias_stddev>0.001</bias_stddev>
              </noise>
            </x>
            <y>
              <noise type="gaussian">
                <mean>0</mean>
                <stddev>0.017</stddev>
                <bias_mean>0.1</bias_mean>
                <bias_stddev>0.001</bias_stddev>
              </noise>
            </y>
            <z>
              <noise type="gaussian">
                <mean>0</mean>
                <stddev>0.017</stddev>
                <bias_mean>0.1</bias_mean>
                <bias_stddev>0.001</bias_stddev>
              </noise>
            </z>
          </linear_acceleration>
        </imu>
        <pose>0 0 0 0 0 0</pose>
      </sensor>
	</link>
	<model name="camera">
      <pose>0 0 0.06 0 1.5709 0</pose>
      <link name="link">
        <inertial>
          <mass>0.1</mass>
           <inertia>
            <ixx>0.000166667</ixx>
            <iyy>0.000166667</iyy>
            <izz>0.000166667</izz>
          </inertia>
        </inertial>
        <collision name="collision">
          <geometry>
            <box>
              <size>0.03 0.03 0.03</size>
            </box>
          </geometry>
        </collision>
        <visual name="visual">
          <geometry>
            <box>
              <size>0.03 0.03 0.03</size>
            </box>
          </geometry>
        </visual>
        <sensor name="camera" type="camera">
          <camera>
            <horizontal_fov>1.5709</horizontal_fov>
            <image>
              <width>320</width>
              <height>240</height>
            </image>
            <clip>
              <near>0.1</near>
              <far>100</far>
            </clip>
          </camera>
          <always_on>1</always_on>
          <update_rate>30</update_rate>
          <visualize>true</visualize>
        </sensor>
      </link>
    </model>
	
    <joint name="joint_camera" type="revolute">
      <child>camera::link</child>
      <parent>quadrotor_link</parent>
      <axis>
        <xyz>0 1 0</xyz>
        <limit>
          <upper>1.5709</upper>
          <lower>-1.5709</lower>
        </limit>
      </axis>
    </joint>
  </model>
</sdf>
